Workbook

Sheet Icindekiler
A2: Emlak Mimarı - Finansal Projeksiyon Modeli
A3: Sürüm: v1.0 | Güncelleme Tarihi: 2026-08-11
A5: Bölüm | B5: Sayfa Adı | C5: Açıklama | D5: İçerdiği Temel Metrikler | E5: Navigasyon
A6: 1 | B6: Icindekiler | C6: Model haritası ve biçimlendirme açıklamaları | D6: Tüm sayfaların listesi ve renk lejantı | E6: =HYPERLINK("#Icindekiler!A1", "Git →") -> Git →
A7: 2 | B7: Varsayimlar | C7: Dinamik senaryo seçici ve finansal girdiler | D7: Dolar Kuru, Ortalama Konut Fiyatı, Senaryolar | E7: =HYPERLINK("#Varsayimlar!A1", "Git →") -> Git →
A8: 3 | B8: Projeksiyonlar | C8: 5 yıllık dinamik gelir ve gider tablosu (TL & USD) | D8: Ciro, Teşvikler, Pazarlama Giderleri, Net Kâr | E8: =HYPERLINK("#Projeksiyonlar!A1", "Git →") -> Git →
A9: 4 | B9: Degerleme_ve_Yatirim | C9: Yatırımcı geri dönüşü ve şirket değerlemesi | D9: EBITDA Çarpanı, Yatırım Getirisi (IRR), Payback | E9: =HYPERLINK("#Degerleme_ve_Yatirim!A1", "Git →") -> Git →
A10: 5 | B10: Grafikler | C10: Finansal büyümeyi gösteren görsel grafikler | D10: Gelir ve EBITDA Gelişimi, Yatırım Dağılımı | E10: =HYPERLINK("#Grafikler!A1", "Git →") -> Git →
A11: 6 | B11: Kontroller | C11: Model formül ve matematik doğrulama tablosu | D11: Formül bütünlüğü ve tutarlılık testleri | E11: =HYPERLINK("#Kontroller!A1", "Git →") -> Git →
A14: Model Biçimlendirme Lejantı
A16: Mavi Dolgu | B16: Girdi Hücresi (Kullanıcı tarafından değiştirilebilir assumptions)
A17: Yeşil Dolgu | B17: Hesaplama Hücresi (Formülle dinamik olarak üretilen sonuçlar)
A18: Açık Sarı Dolgu | B18: Geçici Veri / Yer Tutucu (İleride gerçek verilerle güncellenmeli)
A19: Koyu Mavi Dolgu | B19: Tablo Başlıkları ve Genel Toplamlar

Sheet Varsayimlar
A2: Emlak Mimarı - Finansal Varsayımlar
A4: AKTİF SENARYO SEÇİCİ | B4: 1 | C4: <- DEĞİŞTİRİN (1 = Taban Senaryo, 2 = İyimser Senaryo, 3 = Kötümser Senaryo)
A6: GENEL PAZAR VARYASYONLARI VE PARAMETRELERİ
A7: Dolar Kuru (USD/TRY) | B7: 48
A8: Yıllık Ortalama Konut Fiyatı (TL) | B8: 6100000
A9: Konut Fiyatı Yıllık Artış Oranı (Enflasyon) | B9: 0.15
A10: Alıcı Komisyon Oranı (%) | B10: 0.02
A11: İstanbul Konut Satış Pazarı (Yıllık Adet) | B11: 286000
A12: Pazar Yıllık Adet Artışı (%) | B12: 7.5%
A13: Talep Edilen Yatırım Tutarı ($) | B13: 350000
A14: Yatırım Karşılığı Teklif Edilen Hisse (%) | B14: 0.2
A16: YATIRIM FONUNUN KULLANIM DAĞILIMI
A17: Pazarlama ve Dijital Reklam bütçesi | B17: 0.6
A18: 3D Kamera ve Çekim Ekipmanı | B18: 0.2
A19: Yazılım ve Sunucu Geliştirme | B19: 0.1
A20: Operasyonel ve Genel Giderler | B20: 0.1
A23: SENARYO MATRİSİ: 5 YILLIK HEDEFLENEN İŞLEM ADETLERİ İSTANBUL
A24: ID | B24: Senaryo Tanımı | C24: Yıl 1 (2026) | D24: Yıl 2 (2027) | E24: Yıl 3 (2028) | F24: Yıl 4 (2029) | G24: Yıl 5 (2030)
A25: 1 | B25: Taban Senaryo (Base Case) | C25: 280 | D25: 820 | E25: 2380 | F25: 5954 | G25: 13000
A26: 2 | B26: İyimser Senaryo (Bull Case) | C26: 400 | D26: 1300 | E26: 3970 | F26: 8661 | G26: 16239
A27: 3 | B27: Kötümser Senaryo (Bear Case) | C27: 140 | D27: 433 | E27: 1083 | F27: 2706 | G27: 5413

Sheet Projeksiyonlar
A2: 5 Yıllık Finansal Gelir ve Gider Projeksiyonları İstanbul
A4: Finansal Göstergeler (TL & USD) | B4: Metodoloji / Referans | C4: 2026 (Yıl 1) | D4: 2027 (Yıl 2) | E4: 2028 (Yıl 3) | F4: 2029 (Yıl 4) | G4: 2030 (Yıl 5)
A5: OPERASYONEL METRİKLER
A6: Başarılı Satış İşlemi Adedi (Konut) | B6: Dinamik Senaryo Seçici | C6: =INDEX(Varsayimlar!$C$25:$G$27, Varsayimlar!$B$4, 1) -> 280 | D6: {=INDEX(Varsayimlar!$C$25:$G$27, Varsayimlar!$B$4, 2)} -> 820 | E6: {=INDEX(Varsayimlar!$C$25:$G$27, Varsayimlar!$B$4, 3)} -> 2380 | F6: {=INDEX(Varsayimlar!$C$25:$G$27, Varsayimlar!$B$4, 4)} -> 5954 | G6: {=INDEX(Varsayimlar!$C$25:$G$27, Varsayimlar!$B$4, 5)} -> 13000
A7: Ortalama Konut Değeri (TL) | B7: Varsayımlar B7 | B8 Artış | C7: =Varsayimlar!$B$8 -> 6100000 | D7: =C7*(1+Varsayimlar!$B$9) -> 7015000 | E7: =D7*(1+Varsayimlar!$B$9) -> 8067250 | F7: =E7*(1+Varsayimlar!$B$9) -> 9277337.5 | G7: =F7*(1+Varsayimlar!$B$9) -> 10668938
A8: Toplam Platform İşlem Hacmi (TL) | B8: İşlem Adedi * Ortalama Fiyat | C8: =C6*C7 -> 1708000000 | D8: =D6*D7 -> 5.7523e+09 | E8: =E6*E7 -> 1.9200055e+10 | F8: =F6*F7 -> 5.5237267e+10 | G8: =G6*G7 -> 1.386962e+11
A9: GELİR TABLOSU (TL)
A10: Satış Komisyonu Geliri (TL) - %2 | B10: İşlem Hacmi * Komisyon Oranı (%2) | C10: =C8*Varsayimlar!$B$10 -> 34160000 | D10: =D8*Varsayimlar!$B$10 -> 1.15046e+08 | E10: =E8*Varsayimlar!$B$10 -> 3.840011e+08 | F10: =F8*Varsayimlar!$B$10 -> 1.1047453e+09 | G10: =G8*Varsayimlar!$B$10 -> 2.7739239e+09
A11: Kiralama Komisyonu Geliri (TL) - (Kira Bedeli vb.) | B11: Satış Gelirinin %35'i | C11: =C10*0.35 -> 11956000 | D11: =D10*0.35 -> 40266100 | E11: =E10*0.35 -> 1.3440038e+08 | F11: =F10*0.35 -> 3.8666087e+08 | G11: =G10*0.35 -> 9.7087337e+08
A12: Premium Hizmetler ve İlan Öne Çıkarma (TL) | B12: Satış Gelirinin %5'u | C12: =C10*0.05 -> 1708000 | D12: =D10*0.05 -> 5752300 | E12: =E10*0.05 -> 19200055 | F12: =F10*0.05 -> 55237267 | G12: =G10*0.05 -> 1.386962e+08
A13: Veri Analitiği ve Geliştirici Raporlama Abonelikleri (TL) | B13: Satış Gelirinin %1'i | C13: =C10*0.01 -> 341600 | D13: =D10*0.01 -> 1150460 | E13: =E10*0.01 -> 3840011 | F13: =F10*0.01 -> 11047453 | G13: =G10*0.01 -> 27739239
A14: Toplam Brüt Gelir (TL) | B14: Gelir Kalemleri Toplamı | C14: =SUM(C10:C13) -> 48165600 | D14: =SUM(D10:D13) -> 1.6221486e+08 | E14: =SUM(E10:E13) -> 5.4144155e+08 | F14: =SUM(F10:F13) -> 1.5576909e+09 | G14: =SUM(G10:G13) -> 3.9112327e+09
A15: Toplam Brüt Gelir (USD) | B15: TL Ciro / Dolar Kuru | C15: =C14/Varsayimlar!$B$7 -> 1003450 | D15: =D14/Varsayimlar!$B$7 -> 3379476.2 | E15: =E14/Varsayimlar!$B$7 -> 11280032 | F15: =F14/Varsayimlar!$B$7 -> 32451895 | G15: =G14/Varsayimlar!$B$7 -> 81484015
A16: FAALİYET GİDERLERİ (TL)
A17: 'Ev Getir Kazan' Satıcı Teşvik Giderleri (TL) | B17: Satış Komisyonu * %15 (Teşvik) | C17: =C10*0.15 -> 5124000 | D17: =D10*0.15 -> 17256900 | E17: =E10*0.15 -> 57600165 | F17: =F10*0.15 -> 1.657118e+08 | G17: =G10*0.15 -> 4.1608859e+08
A18: Pazarlama ve Dijital Reklam Giderleri (TL) | B18: Y1 Yatırımın %60'ı | Sonra %15 Ciro | C18: =Varsayimlar!$B$13*Varsayimlar!$B$17*Varsayimlar!$B$7 -> 10080000 | D18: =D14*0.15 -> 24332229 | E18: =E14*0.15 -> 81216233 | F18: =F14*0.15 -> 2.3365364e+08 | G18: =G14*0.15 -> 5.8668491e+08
A19: Yazılım Bakım ve Sunucu Giderleri (TL) | B19: Y1 %10 Fon | Sonra %15 Artış | C19: =Varsayimlar!$B$13*Varsayimlar!$B$19*Varsayimlar!$B$7 -> 1680000 | D19: =C19*1.15 -> 1932000 | E19: =D19*1.15 -> 2221800 | F19: =E19*1.15 -> 2555070 | G19: =F19*1.15 -> 2938330.5
A20: Ekipman Amortismanı ve Çekim Giderleri (TL) | B20: Y1 %20 Fon | Sonra %10 Artış | C20: =Varsayimlar!$B$13*Varsayimlar!$B$18*Varsayimlar!$B$7 -> 3360000 | D20: =C20*1.1 -> 3696000 | E20: =D20*1.1 -> 4065600 | F20: =E20*1.1 -> 4472160 | G20: =F20*1.1 -> 4919376
A21: Personel ve Ekip Maaş Giderleri (TL) | B21: Y1: 5 Pers. | Y5: 20 Pers. Planı | C21: 2100000 | D21: 3840000 | E21: 6912000 | F21: 12528000 | G21: 21000000
A22: Genel Yönetim ve Kurumsal Giderler (TL) | B22: Y1 %10 Fon | Sonra %10 Artış | C22: =Varsayimlar!$B$13*Varsayimlar!$B$20*Varsayimlar!$B$7 -> 1680000 | D22: =C22*1.1 -> 1848000 | E22: =D22*1.1 -> 2032800 | F22: =E22*1.1 -> 2236080 | G22: =F22*1.1 -> 2459688
A23: Toplam Faaliyet Giderleri (OPEX) (TL) | B23: Faaliyet Giderleri Toplamı | C23: =SUM(C17:C22) -> 24024000 | D23: =SUM(D17:D22) -> 52905129 | E23: =SUM(E17:E22) -> 1.540486e+08 | F23: =SUM(F17:F22) -> 4.2115675e+08 | G23: =SUM(G17:G22) -> 1.0340909e+09
A24: Toplam Faaliyet Giderleri (OPEX) (USD) | B24: TL OPEX / Dolar Kuru | C24: =C23/Varsayimlar!$B$7 -> 500500 | D24: =D23/Varsayimlar!$B$7 -> 1102190.2 | E24: =E23/Varsayimlar!$B$7 -> 3209345.8 | F24: =F23/Varsayimlar!$B$7 -> 8774099 | G24: =G23/Varsayimlar!$B$7 -> 21543560
A25: FİNANSAL ÖZET & KÂRLILIK
A26: FAVÖK (EBITDA) (TL) | B26: Ciro (TL) - OPEX (TL) | C26: =C14-C23 -> 24141600 | D26: =D14-D23 -> 1.0930973e+08 | E26: =E14-E23 -> 3.8739295e+08 | F26: =F14-F23 -> 1.1365342e+09 | G26: =G14-G23 -> 2.8771418e+09
A27: FAVÖK (EBITDA) (USD) | B27: TL EBITDA / Dolar Kuru | C27: =C26/Varsayimlar!$B$7 -> 502950 | D27: =D26/Varsayimlar!$B$7 -> 2277286.1 | E27: =E26/Varsayimlar!$B$7 -> 8070686.5 | F27: =F26/Varsayimlar!$B$7 -> 23677796 | G27: =G26/Varsayimlar!$B$7 -> 59940455
A28: FAVÖK Marjı (%) | B28: EBITDA / Toplam Gelir | C28: =IFERROR(C26/C14, 0) -> 0.50122079 | D28: =IFERROR(D26/D14, 0) -> 0.67385769 | E28: =IFERROR(E26/E14, 0) -> 0.71548434 | F28: =IFERROR(F26/F14, 0) -> 0.72962753 | G28: =IFERROR(G26/G14, 0) -> 0.73560998
A29: Amortisman Gideri (TL) | B29: Kamera & Ekipman / 5 Yıl | C29: =C20/5 -> 672000 | D29: =D20/5 -> 739200 | E29: =E20/5 -> 813120 | F29: =F20/5 -> 894432 | G29: =G20/5 -> 983875.2
A30: Kurumlar Vergisi (%20) (TL) | B30: Pozitif Kâr üzerinden %20 Vergi | C30: =IF((C26-C29)>0, (C26-C29)*0.2, 0) -> 4693920 | D30: =IF((D26-D29)>0, (D26-D29)*0.2, 0) -> 21714106 | E30: =IF((E26-E29)>0, (E26-E29)*0.2, 0) -> 77315967 | F30: =IF((F26-F29)>0, (F26-F29)*0.2, 0) -> 2.2712795e+08 | G30: =IF((G26-G29)>0, (G26-G29)*0.2, 0) -> 5.7523159e+08
A31: Net Dönem Kârı (TL) | B31: EBITDA - Amortisman - Vergi | C31: =C26-C29-C30 -> 18775680 | D31: =D26-D29-D30 -> 86856425 | E31: =E26-E29-E30 -> 3.0926387e+08 | F31: =F26-F29-F30 -> 9.0851181e+08 | G31: =G26-G29-G30 -> 2.3009264e+09
A32: Net Dönem Kârı (USD) | B32: TL Net Kâr / Dolar Kuru | C32: =C31/Varsayimlar!$B$7 -> 391160 | D32: =D31/Varsayimlar!$B$7 -> 1809508.8 | E32: =E31/Varsayimlar!$B$7 -> 6442997.2 | F32: =F31/Varsayimlar!$B$7 -> 18927329 | G32: =G31/Varsayimlar!$B$7 -> 47935966
A33: Net Kâr Marjı (%) | B33: Net Kâr / Toplam Gelir | C33: =IFERROR(C31/C14, 0) -> 0.38981514 | D33: =IFERROR(D31/D14, 0) -> 0.53544062 | E33: =IFERROR(E31/E14, 0) -> 0.57118606 | F33: =IFERROR(F31/F14, 0) -> 0.58324266 | G33: =IFERROR(G31/G14, 0) -> 0.58828674

Sheet Degerleme_ve_Yatirim
A2: Emlak Mimarı - Şirket Değerlemesi ve Yatırımcı Geri Dönüşü
A4: 5. YIL SONU ŞİRKET DEĞERLEMESİ
A5: EBITDA Çarpanı (Sektör Standardı) | B5: 10 | C5: <- Yatırımcı için varsayılan çarpan
A6: 5. Yıl Sonu EBITDA (USD) | B6: =Projeksiyonlar!G27 -> 59940455
A7: Girişim Değeri (USD) (Enterprise Value) | B7: =B5*B6 -> 5.9940455e+08
A10: YATIRIMCI GERİ DÖNÜŞÜ (350.000 $ YATIRIM İÇİN)
A11: Talep Edilen Yatırım Tutarı ($) | B11: =Varsayimlar!$B$13 -> 350000
A12: Teklif Edilen Hisse (%) | B12: =Varsayimlar!$B$14 -> 0.2
A13: 5. Yıl Sonu Yatırımcı Hisse Değeri (USD) | B13: =B7*B12 -> 1.1988091e+08
A14: Yatırım Çarpanı (MOIC) | B14: =B13/B11 -> 342.51688
A15: İç Verim Oranı (IRR) | B15: =(B14)^(1/5)-1 -> 2.2131899
A18: YATIRIM GERİ ÖDEME (PAYBACK) VE NAKİT AKIŞ ANALİZİ
A19: Metrik (USD) | B19: Yıl 0 (Bugün) | C19: Yıl 1 (2026) | D19: Yıl 2 (2027) | E19: Yıl 3 (2028) | F19: Yıl 4 (2029) | G19: Yıl 5 (2030)
A20: Yatırımcı Nakit Akışı (Girdi/Kâr Payı) | B20: =-B11 -> -350000 | C20: =Projeksiyonlar!C32*$B$12 -> 78232 | D20: =Projeksiyonlar!D32*$B$12 -> 361901.77 | E20: =Projeksiyonlar!E32*$B$12 -> 1288599.4 | F20: =Projeksiyonlar!F32*$B$12 -> 3785465.9 | G20: =Projeksiyonlar!G32*$B$12 -> 9587193.2
A21: Kümülatif Nakit Akışı | B21: =B20 -> -350000 | C21: =B21+C20 -> -271768 | D21: =C21+D20 -> 90133.77 | E21: =D21+E20 -> 1378733.2 | F21: =E21+F20 -> 5164199.1 | G21: =F21+G20 -> 14751392
A22: Yatırım Geri Dönüş Durumu | B22: Yatırım Yapıldı | C22: =IF(AND(B21<0, C21>=0), "Geri Ödeme Sağlandı!", IF(C21>=0, "Kârlı Dönem", "Devam Ediyor")) -> Devam Ediyor | D22: =IF(AND(C21<0, D21>=0), "Geri Ödeme Sağlandı!", IF(D21>=0, "Kârlı Dönem", "Devam Ediyor")) -> Geri Ödeme Sağlandı! | E22: =IF(AND(D21<0, E21>=0), "Geri Ödeme Sağlandı!", IF(E21>=0, "Kârlı Dönem", "Devam Ediyor")) -> Kârlı Dönem | F22: =IF(AND(E21<0, F21>=0), "Geri Ödeme Sağlandı!", IF(F21>=0, "Kârlı Dönem", "Devam Ediyor")) -> Kârlı Dönem | G22: =IF(AND(F21<0, G21>=0), "Geri Ödeme Sağlandı!", IF(G21>=0, "Kârlı Dönem", "Devam Ediyor")) -> Kârlı Dönem

Sheet Grafikler
A2: Emlak Mimarı - Projeksiyon Grafikleri ve Görsel Veri Paneli
A4: GRAFİK VERİ KAYNAKLARI (Dinmikte Bağlıdır) | H4: YATIRIM FONU KULLANIM KIRILIMI
A5: Metrik (USD) | B5: 2026 | C5: 2027 | D5: 2028 | E5: 2029 | F5: 2030 | H5: Kullanım Alanı | I5: Yüzde (%)
A6: Toplam Brüt Gelir (USD) | B6: =Projeksiyonlar!C15 -> 1003450 | C6: =Projeksiyonlar!D15 -> 3379476.2 | D6: =Projeksiyonlar!E15 -> 11280032 | E6: =Projeksiyonlar!F15 -> 32451895 | F6: =Projeksiyonlar!G15 -> 81484015 | H6: Pazarlama & Reklam | I6: =Varsayimlar!$B$17 -> 0.6
A7: FAVÖK (EBITDA) (USD) | B7: =Projeksiyonlar!C27 -> 502950 | C7: =Projeksiyonlar!D27 -> 2277286.1 | D7: =Projeksiyonlar!E27 -> 8070686.5 | E7: =Projeksiyonlar!F27 -> 23677796 | F7: =Projeksiyonlar!G27 -> 59940455 | H7: 3D Ekipman & Çekim | I7: =Varsayimlar!$B$18 -> 0.2
A8: Net Dönem Kârı (USD) | B8: =Projeksiyonlar!C32 -> 391160 | C8: =Projeksiyonlar!D32 -> 1809508.8 | D8: =Projeksiyonlar!E32 -> 6442997.2 | E8: =Projeksiyonlar!F32 -> 18927329 | F8: =Projeksiyonlar!G32 -> 47935966 | H8: Yazılım & Altyapı | I8: =Varsayimlar!$B$19 -> 0.1
H9: Operasyonel & Kurumsal | I9: =Varsayimlar!$B$20 -> 0.1

Sheet Kontroller
A2: Emlak Mimarı - Finansal Model Güvenilirlik Testleri
A4: No | B4: Güvenilirlik Test Adı | C4: Hedeflenen Değer | D4: Gerçekleşen / Fark | E4: Test Sonucu
A5: 1 | B5: Ciro Tutarlılık Testi (TL Brüt Gelir vs Toplam Parçalar) | C5: 0 | D5: =Projeksiyonlar!C14-SUM(Projeksiyonlar!C10:'Projeksiyonlar'!C13) -> 0 | E5: =IF(ABS(D5)<0.01, "BAŞARILI ✅", "HATA ❌") -> BAŞARILI ✅
A6: 2 | B6: Döviz Çevrim Kontrolü (TL Ciro / Kur - USD Ciro) | C6: 0 | D6: =Projeksiyonlar!C15-(Projeksiyonlar!C14/Varsayimlar!$B$7) -> 0 | E6: =IF(ABS(D6)<0.01, "BAŞARILI ✅", "HATA ❌") -> BAŞARILI ✅
A7: 3 | B7: EBITDA Matematiksel Tutarlılığı (TL Ciro - TL OPEX - EBITDA) | C7: 0 | D7: =Projeksiyonlar!C26-(Projeksiyonlar!C14-Projeksiyonlar!C23) -> 0 | E7: =IF(ABS(D7)<0.01, "BAŞARILI ✅", "HATA ❌") -> BAŞARILI ✅
A8: 4 | B8: Net Kâr Doğruluk Kontrolü (EBITDA - Amortisman - Vergi - Net Kâr) | C8: 0 | D8: =Projeksiyonlar!C31-(Projeksiyonlar!C26-Projeksiyonlar!C29-Projeksiyonlar!C30) -> 0 | E8: =IF(ABS(D8)<0.01, "BAŞARILI ✅", "HATA ❌") -> BAŞARILI ✅

Sheet VarsayimlarHedefli
A2: Emlak Mimarı - Finansal Varsayımlar
A4: AKTİF SENARYO SEÇİCİ | B4: 5 | C4: <- DEĞİŞTİRİN (4 = Taban Senaryo, 5 = İyimser Senaryo, 6 = Kötümser Senaryo)
A6: ANKARA İZMİR VE TÜRKİYE İÇİN VERİLER | B6: VERİLER | C6: 2027 | D6: 2028 | E6: 2029 | F6: 2030
A7: Dolar Kuru (USD/TRY) | B7: 48
A8: Konut Fiyatı Yıllık Artış Oranı (Enflasyon) | B8: 0.15
A9: Alıcı Komisyon Oranı (%) | B9: 0.02
A10: İstanbul Konut Satış Pazarı (Yıllık Adet) | B10: 286000
A11: Pazar Yıllık Adet Artışı (%) | B11: 0.075
A12: Talep Edilen Yatırım Tutarı ($) | B12: 350000
A13: Yatırım Karşılığı Teklif Edilen Hisse (%) | B13: 0.2
A14: Yıllık Ortalama Konut Fiyatı İSTANBUL (TL) | B14: 6100000 | C14: =Tablo3[[#This Row],[VERİLER]]*(1+B8) -> 7015000 | D14: =Tablo3[[#This Row],[2027]]*(1+B8) -> 8067250 | E14: =Tablo3[[#This Row],[2028]]*(1+B8) -> 9277337.5 | F14: =Tablo3[[#This Row],[2028]]*(1+B8) -> 9277337.5
A15: Yıllık Ortalama Konut Fiyatı ANKARA (TL) | B15: 5027620 | C15: =Tablo3[[#This Row],[VERİLER]]*(1+B8) -> 5781763 | D15: =Tablo3[[#This Row],[2027]]*(1+B8) -> 6649027.4 | E15: =Tablo3[[#This Row],[2028]]*(1+B8) -> 7646381.6 | F15: =Tablo3[[#This Row],[2028]]*(1+B8) -> 7646381.6
A16: Yıllık Ortalama Konut Fiyatı İZMİR (TL) | B16: 6000000 | C16: =Tablo3[[#This Row],[VERİLER]]*(1+B8) -> 6900000 | D16: =Tablo3[[#This Row],[2027]]*(1+B8) -> 7935000 | E16: =Tablo3[[#This Row],[2028]]*(1+B8) -> 9125250 | F16: =Tablo3[[#This Row],[2028]]*(1+B8) -> 9125250
A17: Yıllık Ortalama Konut Fiyatı TÜRKİYE (TL) | B17: 5212875 | C17: =Tablo3[[#This Row],[VERİLER]]*(1+B8) -> 5994806.2 | D17: =Tablo3[[#This Row],[2027]]*(1+B8) -> 6894027.2 | E17: =Tablo3[[#This Row],[2028]]*(1+B8) -> 7928131.3 | F17: =Tablo3[[#This Row],[2028]]*(1+B8) -> 7928131.3
A18: Ankara Konut Satış Pazarı (Yıllık Adet) | B18: 150000 | C18: =B18+(B18*B11) -> 161250 | D18: =C18+(C18*B11) -> 173343.75 | E18: =D18+(D18*B11) -> 186344.53 | F18: =E18+(E18*B11) -> 200320.37
A19: İzmir Konut Satış Pazarı (Yıllık Adet) | B19: 96000 | C19: =B19+(B19*B11) -> 103200 | D19: =C19+(C19*B11) -> 110940 | E19: =D19+(D19*B11) -> 119260.5 | F19: =E19+(E19*B11) -> 128205.04
A20: Türkiye Konut Satış Pazarı (Yıllık Adet) | B20: 1300000 | C20: =B20+(B20*B11) -> 1397500 | D20: =C20+(C20*B11) -> 1502312.5 | E20: =D20+(D20*B11) -> 1614985.9 | F20: =E20+(E20*B11) -> 1736109.9
A28: SENARYO MATRİSİ: ANKARA - İZMİR - TÜRKİYE HEDEFLERİNE GÖRE
A29: ID | B29: Senaryo Tanımı | C29: ANKARA - İZMİR 2027 | D29: ANKARA - İZMİR 2028 | E29: TÜRKİYE 2029 | F29: TÜRKİYE 2030
B30: Taban Senaryo (Base Case) | C30: =(VarsayimlarHedefli!C18+VarsayimlarHedefli!C19)*0.001 -> 264.45 | D30: =(VarsayimlarHedefli!D18+VarsayimlarHedefli!D19)*0.001 -> 284.28375 | E30: =VarsayimlarHedefli!E20*0.001 -> 1614.9859 | F30: =VarsayimlarHedefli!F20*0.001 -> 1736.1099
B31: İyimser Senaryo (Bull Case) | C31: =(VarsayimlarHedefli!C18+VarsayimlarHedefli!C19)*0.003 -> 793.35 | D31: =(VarsayimlarHedefli!D18+VarsayimlarHedefli!D19)*0.003 -> 852.85125 | E31: =VarsayimlarHedefli!E20*0.003 -> 4844.9578 | F31: =VarsayimlarHedefli!F20*0.003 -> 5208.3296
B32: Kötümser Senaryo (Bear Case) | C32: =(VarsayimlarHedefli!C18+VarsayimlarHedefli!C19)*0.0005 -> 132.225 | D32: =(VarsayimlarHedefli!D18+VarsayimlarHedefli!D19)*0.0005 -> 142.14187 | E32: =VarsayimlarHedefli!E20*0.0005 -> 807.49297 | F32: =VarsayimlarHedefli!F20*0.0005 -> 868.05494
A36: SENARYO MATRİSİ: İSTANBUL - ANKARA - İZMİR - TÜRKİYE HEDEFLERİNE GÖRE
A37: ID | B37: Senaryo Tanımı | C37: Yıl 1 (2026) | D37: Yıl 2 (2027) | E37: Yıl 3 (2028) | F37: Yıl 4 (2029) | G37: Yıl 5 (2030)
A38: 4 | B38: Taban Senaryo (Base Case) | C38: 280 | D38: =Varsayimlar!D25+C30 -> 1084.45 | E38: =Varsayimlar!E25+D30 -> 2664.2838 | F38: =Varsayimlar!F25+E30 -> 7568.9859 | G38: =Varsayimlar!G25+F30 -> 14736.11
A39: 5 | B39: İyimser Senaryo (Bull Case) | C39: 400 | D39: =Varsayimlar!D26+C31 -> 2093.35 | E39: =Varsayimlar!E26+D31 -> 4822.8512 | F39: =Varsayimlar!F26+E31 -> 13505.958 | G39: =Varsayimlar!G26+F31 -> 21447.33
A40: 6 | B40: Kötümser Senaryo (Bear Case) | C40: 140 | D40: =Varsayimlar!D27+C32 -> 565.225 | E40: =Varsayimlar!E27+D32 -> 1225.1419 | F40: =Varsayimlar!F27+E32 -> 3513.493 | G40: =Varsayimlar!G27+F32 -> 6281.0549

Sheet ProjeksiyonlarHedefli
A1: 5 Yıllık Finansal Gelir ve Gider Projeksiyonları Hedefli
A3: Finansal Göstergeler (TL & USD) | B3: Metodoloji / Referans | C3: 2026 (Yıl 1) | D3: 2027 (Yıl 2) | E3: 2028 (Yıl 3) | F3: 2029 (Yıl 4) | G3: 2030 (Yıl 5)
A4: OPERASYONEL METRİKLER
A5: Başarılı Satış İşlemi Adedi (Konut) | B5: Dinamik Senaryo Seçici | C5: =INDEX(VarsayimlarHedefli!$C$38:$G$40,VarsayimlarHedefli!$B$4-3,1) -> 400 | D5: =INDEX(VarsayimlarHedefli!$C$38:$G$40,VarsayimlarHedefli!$B$4-3,2) -> 2093.35 | E5: =INDEX(VarsayimlarHedefli!$C$38:$G$40,VarsayimlarHedefli!$B$4-3,3) -> 4822.8512 | F5: =INDEX(VarsayimlarHedefli!$C$38:$G$40,VarsayimlarHedefli!$B$4-3,4) -> 13505.958 | G5: =INDEX(VarsayimlarHedefli!$C$38:$G$40,VarsayimlarHedefli!$B$4-3,5) -> 21447.33
A6: Ortalama Konut Değeri (TL) | B6: Varsayımlar B7 | B8 Artış | C6: =Varsayimlar!$B$8 -> 6100000 | D6: =C6*(1+Varsayimlar!$B$9) -> 7015000 | E6: =D6*(1+Varsayimlar!$B$9) -> 8067250 | F6: =E6*(1+Varsayimlar!$B$9) -> 9277337.5 | G6: =F6*(1+Varsayimlar!$B$9) -> 10668938
A7: Toplam Platform İşlem Hacmi (TL) | B7: İşlem Adedi * Ortalama Fiyat | C7: =C5*C6 -> 2440000000 | D7: =D5*D6 -> 1.468485e+10 | E7: =E5*E6 -> 3.8907147e+10 | F7: =F5*F6 -> 1.2529933e+11 | G7: =G5*G6 -> 2.2882023e+11
A8: GELİR TABLOSU (TL)
A9: Satış Komisyonu Geliri (TL) - %2 | B9: İşlem Hacmi * Komisyon Oranı (%2) | C9: =C7*Varsayimlar!$B$10 -> 48800000 | D9: =D7*Varsayimlar!$B$10 -> 2.93697e+08 | E9: =E7*Varsayimlar!$B$10 -> 7.7814293e+08 | F9: =F7*Varsayimlar!$B$10 -> 2.5059866e+09 | G9: =G7*Varsayimlar!$B$10 -> 4.5764047e+09
A10: Kiralama Komisyonu Geliri (TL) - (Kira Bedeli vb.) | B10: Satış Gelirinin %35'i | C10: =C9*0.35 -> 17080000 | D10: =D9*0.35 -> 1.0279395e+08 | E10: =E9*0.35 -> 2.7235003e+08 | F10: =F9*0.35 -> 8.770953e+08 | G10: =G9*0.35 -> 1.6017416e+09
A11: Premium Hizmetler ve İlan Öne Çıkarma (TL) | B11: Satış Gelirinin %5'u | C11: =C9*0.05 -> 2440000 | D11: =D9*0.05 -> 14684850 | E11: =E9*0.05 -> 38907147 | F11: =F9*0.05 -> 1.2529933e+08 | G11: =G9*0.05 -> 2.2882023e+08
A12: Veri Analitiği ve Geliştirici Raporlama Abonelikleri (TL) | B12: Satış Gelirinin %1'i | C12: =C9*0.01 -> 488000 | D12: =D9*0.01 -> 2936970 | E12: =E9*0.01 -> 7781429.3 | F12: =F9*0.01 -> 25059866 | G12: =G9*0.01 -> 45764047
A13: Toplam Brüt Gelir (TL) | B13: Gelir Kalemleri Toplamı | C13: =SUM(C9:C12) -> 68808000 | D13: =SUM(D9:D12) -> 4.1411278e+08 | E13: =SUM(E9:E12) -> 1.0971815e+09 | F13: =SUM(F9:F12) -> 3.5334411e+09 | G13: =SUM(G9:G12) -> 6.4527306e+09
A14: Toplam Brüt Gelir (USD) | B14: TL Ciro / Dolar Kuru | C14: =C13/Varsayimlar!$B$7 -> 1433500 | D14: =D13/Varsayimlar!$B$7 -> 8627349.5 | E14: =E13/Varsayimlar!$B$7 -> 22857949 | F14: =F13/Varsayimlar!$B$7 -> 73613356 | G14: =G13/Varsayimlar!$B$7 -> 1.3443189e+08
A15: FAALİYET GİDERLERİ (TL)
A16: 'Ev Getir Kazan' Satıcı Teşvik Giderleri (TL) | B16: Satış Komisyonu * %15 (Teşvik) | C16: =C9*0.15 -> 7320000 | D16: =D9*0.15 -> 44054551 | E16: =E9*0.15 -> 1.1672144e+08 | F16: =F9*0.15 -> 3.7589799e+08 | G16: =G9*0.15 -> 6.864607e+08
A17: Pazarlama ve Dijital Reklam Giderleri (TL) | B17: Y1 Yatırımın %60'ı | Sonra %15 Ciro | C17: =Varsayimlar!$B$13*Varsayimlar!$B$17*Varsayimlar!$B$7 -> 10080000 | D17: =D13*0.15 -> 62116917 | E17: =E13*0.15 -> 1.6457723e+08 | F17: =F13*0.15 -> 5.3001616e+08 | G17: =G13*0.15 -> 9.6790959e+08
A18: Yazılım Bakım ve Sunucu Giderleri (TL) | B18: Y1 %10 Fon | Sonra %15 Artış | C18: =Varsayimlar!$B$13*Varsayimlar!$B$19*Varsayimlar!$B$7 -> 1680000 | D18: =C18*1.15 -> 1932000 | E18: =D18*1.15 -> 2221800 | F18: =E18*1.15 -> 2555070 | G18: =F18*1.15 -> 2938330.5
A19: Ekipman Amortismanı ve Çekim Giderleri (TL) | B19: Y1 %20 Fon | Sonra %10 Artış | C19: =Varsayimlar!$B$13*Varsayimlar!$B$18*Varsayimlar!$B$7 -> 3360000 | D19: =C19*1.1 -> 3696000 | E19: =D19*1.1 -> 4065600 | F19: =E19*1.1 -> 4472160 | G19: =F19*1.1 -> 4919376
A20: Personel ve Ekip Maaş Giderleri (TL) | B20: Y1: 5 Pers. | Y5: 20 Pers. Planı | C20: 2100000 | D20: 3840000 | E20: 6912000 | F20: 12528000 | G20: 21000000
A21: Genel Yönetim ve Kurumsal Giderler (TL) | B21: Y1 %10 Fon | Sonra %10 Artış | C21: =Varsayimlar!$B$13*Varsayimlar!$B$20*Varsayimlar!$B$7 -> 1680000 | D21: =C21*1.1 -> 1848000 | E21: =D21*1.1 -> 2032800 | F21: =E21*1.1 -> 2236080 | G21: =F21*1.1 -> 2459688
A22: Toplam Faaliyet Giderleri (OPEX) (TL) | B22: Faaliyet Giderleri Toplamı | C22: =SUM(C16:C21) -> 26220000 | D22: =SUM(D16:D21) -> 1.1748747e+08 | E22: =SUM(E16:E21) -> 2.9653087e+08 | F22: =SUM(F16:F21) -> 9.2770546e+08 | G22: =SUM(G16:G21) -> 1.6856877e+09
A23: Toplam Faaliyet Giderleri (OPEX) (USD) | B23: TL OPEX / Dolar Kuru | C23: =C22/Varsayimlar!$B$7 -> 546250 | D23: =D22/Varsayimlar!$B$7 -> 2447655.6 | E23: =E22/Varsayimlar!$B$7 -> 6177726.5 | F23: =F22/Varsayimlar!$B$7 -> 19327197 | G23: =G22/Varsayimlar!$B$7 -> 35118493
A24: FİNANSAL ÖZET & KÂRLILIK
A25: FAVÖK (EBITDA) (TL) | B25: Ciro (TL) - OPEX (TL) | C25: =C13-C22 -> 42588000 | D25: =D13-D22 -> 2.9662531e+08 | E25: =E13-E22 -> 8.0065067e+08 | F25: =F13-F22 -> 2.6057356e+09 | G25: =G13-G22 -> 4.7670429e+09
A26: FAVÖK (EBITDA) (USD) | B26: TL EBITDA / Dolar Kuru | C26: =C25/Varsayimlar!$B$7 -> 887250 | D26: =D25/Varsayimlar!$B$7 -> 6179694 | E26: =E25/Varsayimlar!$B$7 -> 16680222 | F26: =F25/Varsayimlar!$B$7 -> 54286159 | G26: =G25/Varsayimlar!$B$7 -> 99313394
A27: FAVÖK Marjı (%) | B27: EBITDA / Toplam Gelir | C27: =IFERROR(C25/C13, 0) -> 0.61893966 | D27: =IFERROR(D25/D13, 0) -> 0.71629113 | E27: =IFERROR(E25/E13, 0) -> 0.729734 | F27: =IFERROR(F25/F13, 0) -> 0.73744986 | G27: =IFERROR(G25/G13, 0) -> 0.73876367
A28: Amortisman Gideri (TL) | B28: Kamera & Ekipman / 5 Yıl | C28: =C19/5 -> 672000 | D28: =D19/5 -> 739200 | E28: =E19/5 -> 813120 | F28: =F19/5 -> 894432 | G28: =G19/5 -> 983875.2
A29: Kurumlar Vergisi (%20) (TL) | B29: Pozitif Kâr üzerinden %20 Vergi | C29: =IF((C25-C28)>0, (C25-C28)*0.2, 0) -> 8383200 | D29: =IF((D25-D28)>0, (D25-D28)*0.2, 0) -> 59177222 | E29: =IF((E25-E28)>0, (E25-E28)*0.2, 0) -> 1.5996751e+08 | F29: =IF((F25-F28)>0, (F25-F28)*0.2, 0) -> 5.2096824e+08 | G29: =IF((G25-G28)>0, (G25-G28)*0.2, 0) -> 9.532118e+08
A30: Net Dönem Kârı (TL) | B30: EBITDA - Amortisman - Vergi | C30: =C25-C28-C29 -> 33532800 | D30: =D25-D28-D29 -> 2.3670889e+08 | E30: =E25-E28-E29 -> 6.3987004e+08 | F30: =F25-F28-F29 -> 2.0838729e+09 | G30: =G25-G28-G29 -> 3.8128472e+09
A31: Net Dönem Kârı (USD) | B31: TL Net Kâr / Dolar Kuru | C31: =C30/Varsayimlar!$B$7 -> 698600 | D31: =D30/Varsayimlar!$B$7 -> 4931435.2 | E31: =E30/Varsayimlar!$B$7 -> 13330626 | F31: =F30/Varsayimlar!$B$7 -> 43414020 | G31: =G30/Varsayimlar!$B$7 -> 79434317
A32: Net Kâr Marjı (%) | B32: Net Kâr / Toplam Gelir | C32: =IFERROR(C30/C13, 0) -> 0.48733868 | D32: =IFERROR(D30/D13, 0) -> 0.57160489 | E32: =IFERROR(E30/E13, 0) -> 0.58319432 | F32: =IFERROR(F30/F13, 0) -> 0.58975738 | G32: =IFERROR(G30/G13, 0) -> 0.59088895
A41: Emlak Mimarı - Şirket Değerlemesi ve Yatırımcı Geri Dönüşü
A43: 5. YIL SONU ŞİRKET DEĞERLEMESİ
A44: EBITDA Çarpanı (Sektör Standardı) | B44: 10 | C44: <- Yatırımcı için varsayılan çarpan
A45: 5. Yıl Sonu EBITDA (USD) | B45: =ProjeksiyonlarHedefli!G26 -> 99313394
A46: Girişim Değeri (USD) (Enterprise Value) | B46: =B44*B45 -> 9.9313394e+08
A49: YATIRIMCI GERİ DÖNÜŞÜ (350.000 $ YATIRIM İÇİN)
A50: Talep Edilen Yatırım Tutarı ($) | B50: =Varsayimlar!$B$13 -> 350000
A51: Teklif Edilen Hisse (%) | B51: =Varsayimlar!$B$14 -> 0.2
A52: 5. Yıl Sonu Yatırımcı Hisse Değeri (USD) | B52: =B46*B51 -> 1.9862679e+08
...
